ERROR 2025-05-18 03:15:03,943 signal 12300 5884 Signal handler <bound method DjangoFixup.on_import_modules of <celery.fixups.django.DjangoFixup object at 0x0000028B88FAB590>> raised: ModuleNotFoundError("No module named 'testing'")
Traceback (most recent call last):
  File "C:\Users\malik\PycharmProjects\Kurrsat\.venv\Lib\site-packages\celery\utils\dispatch\signal.py", line 280, in send
    response = receiver(signal=self, sender=sender, **named)
               ^^^^^^^^^^^^^^^^^^^^^^^^^^^^^^^^^^^^^^^^^^^^^
  File "C:\Users\malik\PycharmProjects\Kurrsat\.venv\Lib\site-packages\celery\fixups\django.py", line 101, in on_import_modules
    self.worker_fixup.validate_models()
  File "C:\Users\malik\PycharmProjects\Kurrsat\.venv\Lib\site-packages\celery\fixups\django.py", line 139, in validate_models
    self.django_setup()
  File "C:\Users\malik\PycharmProjects\Kurrsat\.venv\Lib\site-packages\celery\fixups\django.py", line 135, in django_setup
    django.setup()
  File "C:\Users\malik\PycharmProjects\Kurrsat\.venv\Lib\site-packages\django\__init__.py", line 24, in setup
    apps.populate(settings.INSTALLED_APPS)
  File "C:\Users\malik\PycharmProjects\Kurrsat\.venv\Lib\site-packages\django\apps\registry.py", line 116, in populate
    app_config.import_models()
  File "C:\Users\malik\PycharmProjects\Kurrsat\.venv\Lib\site-packages\django\apps\config.py", line 269, in import_models
    self.models_module = import_module(models_module_name)
                         ^^^^^^^^^^^^^^^^^^^^^^^^^^^^^^^^^
  File "C:\Users\malik\AppData\Local\Programs\Python\Python312\Lib\importlib\__init__.py", line 90, in import_module
    return _bootstrap._gcd_import(name[level:], package, level)
           ^^^^^^^^^^^^^^^^^^^^^^^^^^^^^^^^^^^^^^^^^^^^^^^^^^^^
  File "<frozen importlib._bootstrap>", line 1387, in _gcd_import
  File "<frozen importlib._bootstrap>", line 1360, in _find_and_load
  File "<frozen importlib._bootstrap>", line 1331, in _find_and_load_unlocked
  File "<frozen importlib._bootstrap>", line 935, in _load_unlocked
  File "<frozen importlib._bootstrap_external>", line 999, in exec_module
  File "<frozen importlib._bootstrap>", line 488, in _call_with_frames_removed
  File "C:\Users\malik\PycharmProjects\Kurrasat\generator\models.py", line 7, in <module>
    from testing.storage_backends import RfpDocumentStorage, ImprovedRfpStorage, OriginalRfpStorage
ModuleNotFoundError: No module named 'testing'
ERROR 2025-05-18 03:15:05,087 signal 12300 5884 Signal handler <promise@0x28b88fafe30 --> <bound method Celery._autodiscover_tasks of <Celery kurrasat at 0x28b88fabe60>>> raised: ModuleNotFoundError("No module named 'testing'")
Traceback (most recent call last):
  File "C:\Users\malik\PycharmProjects\Kurrsat\.venv\Lib\site-packages\celery\utils\dispatch\signal.py", line 280, in send
    response = receiver(signal=self, sender=sender, **named)
               ^^^^^^^^^^^^^^^^^^^^^^^^^^^^^^^^^^^^^^^^^^^^^
  File "C:\Users\malik\PycharmProjects\Kurrsat\.venv\Lib\site-packages\vine\promises.py", line 161, in __call__
    return self.throw()
           ^^^^^^^^^^^^
  File "C:\Users\malik\PycharmProjects\Kurrsat\.venv\Lib\site-packages\vine\promises.py", line 158, in __call__
    retval = fun(*final_args, **final_kwargs)
             ^^^^^^^^^^^^^^^^^^^^^^^^^^^^^^^^
  File "C:\Users\malik\PycharmProjects\Kurrsat\.venv\Lib\site-packages\celery\app\base.py", line 788, in _autodiscover_tasks
    return self._autodiscover_tasks_from_fixups(related_name)
           ^^^^^^^^^^^^^^^^^^^^^^^^^^^^^^^^^^^^^^^^^^^^^^^^^^
  File "C:\Users\malik\PycharmProjects\Kurrsat\.venv\Lib\site-packages\celery\app\base.py", line 797, in _autodiscover_tasks_from_fixups
    return self._autodiscover_tasks_from_names([
           ^^^^^^^^^^^^^^^^^^^^^^^^^^^^^^^^^^^^^
  File "C:\Users\malik\PycharmProjects\Kurrsat\.venv\Lib\site-packages\celery\app\base.py", line 792, in _autodiscover_tasks_from_names
    return self.loader.autodiscover_tasks(
           ^^^^^^^^^^^^^^^^^^^^^^^^^^^^^^^
  File "C:\Users\malik\PycharmProjects\Kurrsat\.venv\Lib\site-packages\celery\loaders\base.py", line 220, in autodiscover_tasks
    mod.__name__ for mod in autodiscover_tasks(packages or (),
                            ^^^^^^^^^^^^^^^^^^^^^^^^^^^^^^^^^^
  File "C:\Users\malik\PycharmProjects\Kurrsat\.venv\Lib\site-packages\celery\loaders\base.py", line 246, in autodiscover_tasks
    return [find_related_module(pkg, related_name) for pkg in packages]
            ^^^^^^^^^^^^^^^^^^^^^^^^^^^^^^^^^^^^^^
  File "C:\Users\malik\PycharmProjects\Kurrsat\.venv\Lib\site-packages\celery\loaders\base.py", line 278, in find_related_module
    raise e
  File "C:\Users\malik\PycharmProjects\Kurrsat\.venv\Lib\site-packages\celery\loaders\base.py", line 270, in find_related_module
    return importlib.import_module(module_name)
           ^^^^^^^^^^^^^^^^^^^^^^^^^^^^^^^^^^^^
  File "C:\Users\malik\AppData\Local\Programs\Python\Python312\Lib\importlib\__init__.py", line 90, in import_module
    return _bootstrap._gcd_import(name[level:], package, level)
           ^^^^^^^^^^^^^^^^^^^^^^^^^^^^^^^^^^^^^^^^^^^^^^^^^^^^
  File "<frozen importlib._bootstrap>", line 1387, in _gcd_import
  File "<frozen importlib._bootstrap>", line 1360, in _find_and_load
  File "<frozen importlib._bootstrap>", line 1331, in _find_and_load_unlocked
  File "<frozen importlib._bootstrap>", line 935, in _load_unlocked
  File "<frozen importlib._bootstrap_external>", line 999, in exec_module
  File "<frozen importlib._bootstrap>", line 488, in _call_with_frames_removed
  File "C:\Users\malik\PycharmProjects\Kurrasat\generator\tasks.py", line 7, in <module>
    from .models import RfpDocument, ImprovedRfpDocument
  File "C:\Users\malik\PycharmProjects\Kurrasat\generator\models.py", line 7, in <module>
    from testing.storage_backends import RfpDocumentStorage, ImprovedRfpStorage, OriginalRfpStorage
ModuleNotFoundError: No module named 'testing'
ERROR 2025-05-18 03:18:04,360 signal 1628 11472 Signal handler <bound method DjangoFixup.on_import_modules of <celery.fixups.django.DjangoFixup object at 0x000002D4DA5A9940>> raised: AttributeError("module 'generator.views' has no attribute 'download_file'")
Traceback (most recent call last):
  File "C:\Users\malik\PycharmProjects\Kurrsat\.venv\Lib\site-packages\celery\utils\dispatch\signal.py", line 280, in send
    response = receiver(signal=self, sender=sender, **named)
               ^^^^^^^^^^^^^^^^^^^^^^^^^^^^^^^^^^^^^^^^^^^^^
  File "C:\Users\malik\PycharmProjects\Kurrsat\.venv\Lib\site-packages\celery\fixups\django.py", line 101, in on_import_modules
    self.worker_fixup.validate_models()
  File "C:\Users\malik\PycharmProjects\Kurrsat\.venv\Lib\site-packages\celery\fixups\django.py", line 141, in validate_models
    run_checks()
  File "C:\Users\malik\PycharmProjects\Kurrsat\.venv\Lib\site-packages\django\core\checks\registry.py", line 89, in run_checks
    new_errors = check(app_configs=app_configs, databases=databases)
                 ^^^^^^^^^^^^^^^^^^^^^^^^^^^^^^^^^^^^^^^^^^^^^^^^^^^
  File "C:\Users\malik\PycharmProjects\Kurrsat\.venv\Lib\site-packages\django\core\checks\urls.py", line 16, in check_url_config
    return check_resolver(resolver)
           ^^^^^^^^^^^^^^^^^^^^^^^^
  File "C:\Users\malik\PycharmProjects\Kurrsat\.venv\Lib\site-packages\django\core\checks\urls.py", line 26, in check_resolver
    return check_method()
           ^^^^^^^^^^^^^^
  File "C:\Users\malik\PycharmProjects\Kurrsat\.venv\Lib\site-packages\django\urls\resolvers.py", line 531, in check
    for pattern in self.url_patterns:
                   ^^^^^^^^^^^^^^^^^
  File "C:\Users\malik\PycharmProjects\Kurrsat\.venv\Lib\site-packages\django\utils\functional.py", line 47, in __get__
    res = instance.__dict__[self.name] = self.func(instance)
                                         ^^^^^^^^^^^^^^^^^^^
  File "C:\Users\malik\PycharmProjects\Kurrsat\.venv\Lib\site-packages\django\urls\resolvers.py", line 718, in url_patterns
    patterns = getattr(self.urlconf_module, "urlpatterns", self.urlconf_module)
                       ^^^^^^^^^^^^^^^^^^^
  File "C:\Users\malik\PycharmProjects\Kurrsat\.venv\Lib\site-packages\django\utils\functional.py", line 47, in __get__
    res = instance.__dict__[self.name] = self.func(instance)
                                         ^^^^^^^^^^^^^^^^^^^
  File "C:\Users\malik\PycharmProjects\Kurrsat\.venv\Lib\site-packages\django\urls\resolvers.py", line 711, in urlconf_module
    return import_module(self.urlconf_name)
           ^^^^^^^^^^^^^^^^^^^^^^^^^^^^^^^^
  File "C:\Users\malik\AppData\Local\Programs\Python\Python312\Lib\importlib\__init__.py", line 90, in import_module
    return _bootstrap._gcd_import(name[level:], package, level)
           ^^^^^^^^^^^^^^^^^^^^^^^^^^^^^^^^^^^^^^^^^^^^^^^^^^^^
  File "<frozen importlib._bootstrap>", line 1387, in _gcd_import
  File "<frozen importlib._bootstrap>", line 1360, in _find_and_load
  File "<frozen importlib._bootstrap>", line 1331, in _find_and_load_unlocked
  File "<frozen importlib._bootstrap>", line 935, in _load_unlocked
  File "<frozen importlib._bootstrap_external>", line 999, in exec_module
  File "<frozen importlib._bootstrap>", line 488, in _call_with_frames_removed
  File "C:\Users\malik\PycharmProjects\Kurrasat\kurrasat\urls.py", line 20, in <module>
    path('generator/', include(('generator.urls', 'generator'), namespace="generator")),
                       ^^^^^^^^^^^^^^^^^^^^^^^^^^^^^^^^^^^^^^^^^^^^^^^^^^^^^^^^^^^^^^^
  File "C:\Users\malik\PycharmProjects\Kurrsat\.venv\Lib\site-packages\django\urls\conf.py", line 39, in include
    urlconf_module = import_module(urlconf_module)
                     ^^^^^^^^^^^^^^^^^^^^^^^^^^^^^
  File "C:\Users\malik\AppData\Local\Programs\Python\Python312\Lib\importlib\__init__.py", line 90, in import_module
    return _bootstrap._gcd_import(name[level:], package, level)
           ^^^^^^^^^^^^^^^^^^^^^^^^^^^^^^^^^^^^^^^^^^^^^^^^^^^^
  File "<frozen importlib._bootstrap>", line 1387, in _gcd_import
  File "<frozen importlib._bootstrap>", line 1360, in _find_and_load
  File "<frozen importlib._bootstrap>", line 1331, in _find_and_load_unlocked
  File "<frozen importlib._bootstrap>", line 935, in _load_unlocked
  File "<frozen importlib._bootstrap_external>", line 999, in exec_module
  File "<frozen importlib._bootstrap>", line 488, in _call_with_frames_removed
  File "C:\Users\malik\PycharmProjects\Kurrasat\generator\urls.py", line 7, in <module>
    path('download/<str:filename>', views.download_file, name='download_file'),
                                    ^^^^^^^^^^^^^^^^^^^
AttributeError: module 'generator.views' has no attribute 'download_file'
